Workbook
Name lista_mun: OFFSET(INDIRECT(#REF!),,,#REF!)
Name resultados_2019: '[1]5'!$B$1:$G$60
Name resultados_2020: '[1]6'!$B$1:$G$60
Name resultados_2021: '[1]7'!$B$1:$G$60
Name niveles: #REF!
Name codmun: #REF!

Sheet Estructura
A1: FACTOR 1 | B1: CONDICIONES HABILITANTES | D1: Periodo | E1: Último | F1: Pilar | G1: Subpilar | H1: Subpilar en el pilar | I1: Variable en el subpilar | J1: Variable en el pilar
A2: PILAR 1: INSTITUCIONES | C2: INVERSA | D2: Corte | E2: Año | F2: =1/13 -> 0.076923077
A3: INS-1 | B3: Desempeño administrativo | G3: =$F$2/4 -> 0.019230769 | H3: =G3/$F$2 -> 0.25 | L3: 2019 | M3: =COUNTIF(E:E,L3) -> 0 | N3: =M3/98 -> 0
A4: INS-1-1 | B4: Gestión de recursos | C4: No | D4: 2019-2022 | E4: =IFERROR(MID(D4,6,4),"") -> 2022 | I4: =1/COUNTBLANK($H$4:$H$6) -> 0.33333333 | J4: =I4*$H$3 -> 0.083333333 | L4: 2020 | M4: =COUNTIF(E:E,L4) -> 0 | N4: =M4/98 -> 0
A5: INS-1-2 | B5: Actualización catastral | C5: Sí | D5: 2018-2022 | E5: =IFERROR(MID(D5,6,4),"") -> 2022 | I5: =1/COUNTBLANK($H$4:$H$6) -> 0.33333333 | J5: =I5*$H$3 -> 0.083333333 | L5: 2021 | M5: =COUNTIF(E:E,L5) -> 4 | N5: =M5/98 -> 0.040816327
A6: INS-1-3 | B6: Índice de Gobierno Digital para el Estado | C6: No | D6: 2022-2023 | E6: =IFERROR(MID(D6,6,4),"") -> 2023 | I6: =1/COUNTBLANK($H$4:$H$6) -> 0.33333333 | J6: =I6*$H$3 -> 0.083333333 | L6: 2022 | M6: =COUNTIF(E:E,L6) -> 36 | N6: =M6/98 -> 0.36734694
A7: INS-2 | B7: Gestión fiscal | E7: =IFERROR(MID(D7,6,4),"") | G7: =$F$2/4 -> 0.019230769 | H7: =G7/$F$2 -> 0.25 | L7: 2023 | M7: =COUNTIF(E:E,L7) -> 55 | N7: =M7/98 -> 0.56122449
A8: INS-2-1 | B8: Autonomía fiscal | C8: No | D8: 2017-2022 | E8: =IFERROR(MID(D8,6,4),"") -> 2022 | I8: =1/COUNTBLANK($H$8:$H$10) -> 0.33333333 | J8: =I8*$H$7 -> 0.083333333 | L8: 2024 | M8: =COUNTIF(E:E,L8) -> 3 | N8: =M8/98 -> 0.030612245
A9: INS-2-2 | B9: Capacidad local de recaudo | C9: No | D9: 2017-2022 | E9: =IFERROR(MID(D9,6,4),"") -> 2022 | I9: =1/COUNTBLANK($H$8:$H$10) -> 0.33333333 | J9: =I9*$H$7 -> 0.083333333
A10: INS-2-3 | B10: Capacidad de ahorro | C10: No | D10: 2017-2022 | E10: =IFERROR(MID(D10,6,4),"") -> 2022 | I10: =1/COUNTBLANK($H$8:$H$10) -> 0.33333333 | J10: =I10*$H$7 -> 0.083333333
A11: INS-3 | B11: Transparencia y contratación pública | E11: =IFERROR(MID(D11,6,4),"") | G11: =$F$2/4 -> 0.019230769 | H11: =G11/$F$2 -> 0.25
A12: INS-3-1 | B12: Índice de Gobierno Digital para la Sociedad | C12: No | D12: 2022-2023 | E12: =IFERROR(MID(D12,6,4),"") -> 2023 | I12: =1/COUNTBLANK($H$12:$H$13) -> 0.5 | J12: =I12*$H$11 -> 0.125
A13: INS-3-2 | B13: Procesos de contratación en SECOP II | C13: No | D13: 2020-2022 | E13: =IFERROR(MID(D13,6,4),"") -> 2022 | I13: =1/COUNTBLANK($H$12:$H$13) -> 0.5 | J13: =I13*$H$11 -> 0.125
A14: INS-4 | B14: Seguridad y justicia | E14: =IFERROR(MID(D14,6,4),"") | G14: =$F$2/4 -> 0.019230769 | H14: =G14/$F$2 -> 0.25
A15: INS-4-1 | B15: Tasa de homicidios | C15: Sí | D15: 2018-2023 | E15: =IFERROR(MID(D15,6,4),"") -> 2023 | I15: =1/COUNTBLANK($H$15:$H$20) -> 0.16666667 | J15: =I15*$H$14 -> 0.041666667
A16: INS-4-2 | B16: Tasa de hurtos | C16: Sí | D16: 2018-2023 | E16: =IFERROR(MID(D16,6,4),"") -> 2023 | I16: =1/COUNTBLANK($H$15:$H$20) -> 0.16666667 | J16: =I16*$H$14 -> 0.041666667
A17: INS-4-3 | B17: Tasa de extorsión | C17: Sí | D17: 2018-2023 | E17: =IFERROR(MID(D17,6,4),"") -> 2023 | I17: =1/COUNTBLANK($H$15:$H$20) -> 0.16666667 | J17: =I17*$H$14 -> 0.041666667
A18: INS-4-4 | B18: Eficiencia de la justicia | C18: No | D18: 2018-2023 | E18: =IFERROR(MID(D18,6,4),"") -> 2023 | I18: =1/COUNTBLANK($H$15:$H$20) -> 0.16666667 | J18: =I18*$H$14 -> 0.041666667
A19: INS-4-5 | B19: Productividad de jueces | C19: No | D19: 2017-2022 | E19: =IFERROR(MID(D19,6,4),"") -> 2022 | I19: =1/COUNTBLANK($H$15:$H$20) -> 0.16666667 | J19: =I19*$H$14 -> 0.041666667
A20: INS-4-6 | B20: Eficiencia de los métodos de resolución de conflictos | C20: No | D20: 2018-2023 | E20: =IFERROR(MID(D20,6,4),"") -> 2023 | I20: =1/COUNTBLANK($H$15:$H$20) -> 0.16666667 | J20: =I20*$H$14 -> 0.041666667
A21: PILAR 2: INFRAESTRUCTURA Y EQUIPAMIENTO | E21: =IFERROR(MID(D21,6,4),"") | F21: =F2 -> 0.076923077
A22: INF-1 | B22: Infraestructura de servicios | E22: =IFERROR(MID(D22,6,4),"") | G22: =$F$21/3 -> 0.025641026 | H22: =G22/$F$21 -> 0.33333333
A23: INF-1-1 | B23: Cobertura de acueducto | C23: No | D23: 2018-2022 | E23: =IFERROR(MID(D23,6,4),"") -> 2022 | I23: =1/COUNTBLANK($H$23:$H$27) -> 0.2 | J23: =I23*$H$22 -> 0.066666667
A24: INF-1-2 | B24: Cobertura efectiva de gas natural | C24: No | D24: 2018-2023 | E24: =IFERROR(MID(D24,6,4),"") -> 2023 | I24: =1/COUNTBLANK($H$23:$H$27) -> 0.2 | J24: =I24*$H$22 -> 0.066666667
A25: INF-1-3 | B25: Cobertura de la energía eléctrica | C25: No | D25: 2018-2023 | E25: =IFERROR(MID(D25,6,4),"") -> 2023 | I25: =1/COUNTBLANK($H$23:$H$27) -> 0.2 | J25: =I25*$H$22 -> 0.066666667
A26: INF-1-4 | B26: Costo de la energía eléctrica | C26: Sí | D26: 2018-2023 | E26: =IFERROR(MID(D26,6,4),"") -> 2023 | I26: =1/COUNTBLANK($H$23:$H$27) -> 0.2 | J26: =I26*$H$22 -> 0.066666667
A27: INF-1-5 | B27: Cobertura de alcantarillado | C27: No | D27: 2018-2022 | E27: =IFERROR(MID(D27,6,4),"") -> 2022 | I27: =1/COUNTBLANK($H$23:$H$27) -> 0.2 | J27: =I27*$H$22 -> 0.066666667
A28: INF-2 | B28: Conectividad | E28: =IFERROR(MID(D28,6,4),"") | G28: =G22 -> 0.025641026 | H28: =G28/$F$21 -> 0.33333333
A29: INF-2-1 | B29: Costo de transporte terrestre a mercado interno | C29: Sí | D29: 2018-2023 | E29: =IFERROR(MID(D29,6,4),"") -> 2023 | I29: =1/COUNTBLANK($H$29:$H$33) -> 0.2 | J29: =I29*$H$28 -> 0.066666667
A30: INF-2-2 | B30: Costo de transporte terrestre a aduanas | C30: Sí | D30: 2018-2023 | E30: =IFERROR(MID(D30,6,4),"") -> 2023 | I30: =1/COUNTBLANK($H$29:$H$33) -> 0.2 | J30: =I30*$H$28 -> 0.066666667
A31: INF-2-3 | B31: Pasajeros movilizados vía aérea | C31: No | D31: 2018-2023 | E31: =IFERROR(MID(D31,6,4),"") -> 2023 | I31: =1/COUNTBLANK($H$29:$H$33) -> 0.2 | J31: =I31*$H$28 -> 0.066666667
A32: INF-2-4 | B32: Índice de conectividad aérea | C32: No | D32: 2018-2023 | E32: =IFERROR(MID(D32,6,4),"") -> 2023 | I32: =1/COUNTBLANK($H$29:$H$33) -> 0.2 | J32: =I32*$H$28 -> 0.066666667
A33: INF-2-5 | B33: Pasajeros movilizados por transporte público | C33: No | D33: 2019-2024 | E33: =IFERROR(MID(D33,6,4),"") -> 2024 | I33: =1/COUNTBLANK($H$29:$H$33) -> 0.2 | J33: =I33*$H$28 -> 0.066666667
A34: INF-3 | B34: Oferta Cultural | E34: =IFERROR(MID(D34,6,4),"") | G34: =G22 -> 0.025641026 | H34: =G34/$F$21 -> 0.33333333
A35: INF-3-1 | B35: Ejemplares de biblioteca | C35: No | D35: 2018-2023 | E35: =IFERROR(MID(D35,6,4),"") -> 2023 | I35: =1/COUNTBLANK($H$35:$H$39) -> 0.2 | J35: =I35*$H$34 -> 0.066666667
A36: INF-3-2 | B36: Museos | C36: No | D36: 2019-2024 | E36: =IFERROR(MID(D36,6,4),"") -> 2024 | I36: =1/COUNTBLANK($H$35:$H$39) -> 0.2 | J36: =I36*$H$34 -> 0.066666667
A37: INF-3-3 | B37: Sillas de sala de cine | C37: No | D37: 2018-2022 | E37: =IFERROR(MID(D37,6,4),"") -> 2022 | I37: =1/COUNTBLANK($H$35:$H$39) -> 0.2 | J37: =I37*$H$34 -> 0.066666667
A38: INF-3-4 | B38: Escenarios culturales | C38: No | D38: 2018-2022 | E38: =IFERROR(MID(D38,6,4),"") -> 2022 | I38: =1/COUNTBLANK($H$35:$H$39) -> 0.2 | J38: =I38*$H$34 -> 0.066666667
A39: INF-3-5 | B39: Bienes de interés cultural | C39: No | D39: 2019-2024 | E39: =IFERROR(MID(D39,6,4),"") -> 2024 | I39: =1/COUNTBLANK($H$35:$H$39) -> 0.2 | J39: =I39*$H$34 -> 0.066666667
A40: PILAR 3: Adopción TIC | E40: =IFERROR(MID(D40,6,4),"") | F40: =F2 -> 0.076923077
...

Sheet INFO_MUN
A1: COD_MUN | B1: CATEGORIA_NUMB | C1: CATEGORIA | D1: POBLACION | E1: ACTIVIDAD_ECONOMICA_PRINCIPAL | F1: PARTICIPACION EN EL PIB

Sheet Valor_normalizado
A1: Ciudad o AM | B1: Año | C1: TIC-1-1 | D1: TIC-1-2 | E1: TIC-1-3 | F1: TIC-1-4 | G1: TIC-1 | H1: TIC-2-1 | I1: TIC-2-2 | J1: TIC-2-3 | K1: TIC-2 | L1: TIC | M1: INN-1-1 | N1: INN-1-2 | O1: INN-1-3 | P1: INN-1-4 | Q1: INN-1-5 | R1: INN-1 | S1: INN-2-1 | T1: INN-2-2 | U1: INN-2-3 | V1: INN-2-4 | W1: INN-2 | X1: INN | Y1: Puntaje general
A2: Bogotá D.C. | B2: 2019 | C2: 8.5442823 | D2: 0.64984122 | E2: 9.5688935 | F2: 9.513601 | G2: 7.0691545 | H2: 4.008368 | I2: 4.8570681 | J2: 8.1711281 | K2: 5.6788547 | L2: 6.3740046 | M2: 3.3282791 | N2: 6.5458141 | O2: 4.7275863 | P2: 9.5964126 | Q2: 2.6636441 | R2: 5.3723472 | S2: 4.7379928 | T2: 6.373097 | U2: 5.4843964 | V2: 7.9192384 | W2: 6.1286811 | X2: 5.7505142 | Y2: 7.0969839
A3: Armenia | B3: 2019 | C3: 8.3033593 | D3: 0.45331118 | E3: 5.5787721 | F3: 6.7736506 | G3: 5.2772733 | H3: 4.1631656 | I3: 3.509322 | J3: 3.5764935 | K3: 3.7496604 | L3: 4.5134668 | M3: 1.3058107 | N3: 0 | O3: 3.4561929 | P3: 7.2197309 | Q3: 3.5420799 | R3: 3.1047629 | S3: 3.2594324 | T3: 4.7066517 | U3: 2.4159861 | V3: 1.7910709 | W3: 3.0432853 | X3: 3.0740241 | Y3: 5.19449
A4: Medellín AM | B4: 2019 | C4: 8.1376696 | D4: 0.58823173 | E4: 7.0745346 | F4: 7.4152837 | G4: 5.8039299 | H4: 3.5794113 | I4: 3.5495899 | J4: 6.9062814 | K4: 4.6784275 | L4: 5.2411787 | M4: 3.5431715 | N4: 4.9254897 | O4: 4.8658925 | P4: 5.7399103 | Q4: 2.7684897 | R4: 4.3685907 | S4: 4.5582072 | T4: 3.3209661 | U4: 7.5559475 | V4: 7.4761023 | W4: 5.7278058 | X4: 5.0481983 | Y4: 6.3363828
A5: Tunja | B5: 2019 | C5: 8.0794028 | D5: 0.40860287 | E5: 6.6634328 | F5: 7.1261968 | G5: 5.5694088 | H5: 8.3119329 | I5: 7.9359201 | J5: 9.5455888 | K5: 8.5978139 | L5: 7.0836114 | M5: 4.7873108 | N5: 10 | O5: 10 | P5: 5.7399103 | Q5: 2.4397846 | R5: 6.5934012 | S5: 0.92941339 | T5: 4.0262456 | U5: 0.82668987 | V5: 1.7391961 | W5: 1.8803862 | X5: 4.2368937 | Y5: 6.199191
A6: Pereira AM | B6: 2019 | C6: 7.3023304 | D6: 0.48920088 | E6: 7.3163081 | F6: 8.9353571 | G6: 6.0107991 | H6: 5.4766318 | I6: 5.2141537 | J6: 4.3842699 | K6: 5.0250185 | L6: 5.5179088 | M6: 1.7780031 | N6: 1.2162941 | O6: 2.2555203 | P6: 5.9192825 | Q6: 4.2774157 | R6: 3.0893031 | S6: 3.1516738 | T6: 3.9008977 | U6: 2.6030966 | V6: 3.1527824 | W6: 3.2021126 | X6: 3.1457079 | Y6: 5.7723183
A7: Bucaramanga AM | B7: 2019 | C7: 7.1779128 | D7: 0.49169784 | E7: 7.0919271 | F7: 7.9844421 | G7: 5.686495 | H7: 3.8020869 | I7: 4.3338245 | J7: 7.8789222 | K7: 5.3382779 | L7: 5.5123864 | M7: 2.7898452 | N7: 3.5979422 | O7: 4.1967489 | P7: 6.0986547 | Q7: 3.2020402 | R7: 3.9770462 | S7: 2.2641633 | T7: 2.3078637 | U7: 2.1323821 | V7: 2.5555855 | W7: 2.3149986 | X7: 3.1460224 | Y7: 5.8728913
A8: Cali AM | B8: 2019 | C8: 7.1138579 | D8: 0.53030973 | E8: 7.23106 | F8: 8.592928 | G8: 5.8670389 | H8: 2.4776346 | I8: 2.8931955 | J8: 5.3908881 | K8: 3.5872394 | L8: 4.7271391 | M8: 3.0895781 | N8: 2.411988 | O8: 3.4681709 | P8: 6.7713004 | Q8: 3.2558799 | R8: 3.7993834 | S8: 2.6785579 | T8: 3.5703354 | U8: 1.89379 | V8: 4.7573384 | W8: 3.2250054 | X8: 3.5121944 | Y8: 6.0173282
A9: Neiva | B9: 2019 | C9: 7.0987445 | D9: 0.34862066 | E9: 5.4600287 | F9: 6.8555359 | G9: 4.9407324 | H9: 3.3449083 | I9: 3.5246472 | J9: 3.3398334 | K9: 3.4031297 | L9: 4.171931 | M9: 1.2326945 | N9: 0 | O9: 1.8882384 | P9: 7.2197309 | Q9: 2.3080193 | R9: 2.5297366 | S9: 2.6923113 | T9: 0 | U9: 0 | V9: 1.3194966 | W9: 1.002952 | X9: 1.7663443 | Y9: 5.0701436
A10: Ibagué | B10: 2019 | C10: 6.996946 | D10: 0.44074085 | E10: 5.9627141 | F10: 7.6113844 | G10: 5.2529463 | H10: 3.8098259 | I10: 6.7486452 | J10: 5.4869113 | K10: 5.3484608 | L10: 5.3007036 | M10: 1.1437374 | N10: 0 | O10: 2.4421457 | P10: 7.3542601 | Q10: 3.5279116 | R10: 2.8936109 | S10: 0.90837136 | T10: 1.311697 | U10: 2.154596 | V10: 1.7762674 | W10: 1.5377329 | X10: 2.2156719 | Y10: 5.2374751
A11: Pasto | B11: 2019 | C11: 6.6202918 | D11: 0.39744649 | E11: 5.7563657 | F11: 6.2261054 | G11: 4.7500523 | H11: 3.4141585 | I11: 4.0217836 | J11: 3.8536312 | K11: 3.7631911 | L11: 4.2566217 | M11: 0.56060259 | N11: 2.2051037 | O11: 3.721162 | P11: 2.9596413 | Q11: 2.71465 | R11: 2.4322319 | S11: 0 | T11: 0 | U11: 0 | V11: 0.69099927 | W11: 0.17274982 | X11: 1.3024909 | Y11: 5.075312
A12: Manizales AM | B12: 2019 | C12: 6.3544402 | D12: 0.42707313 | E12: 7.0595178 | F12: 7.3179389 | G12: 5.2897425 | H12: 4.5849509 | I12: 6.0327542 | J12: 10 | K12: 6.8725684 | L12: 6.0811554 | M12: 6.5104933 | N12: 7.8128289 | O12: 6.390936 | P12: 4.3497758 | Q12: 3.1864551 | R12: 5.6500978 | S12: 2.8920976 | T12: 4.8722529 | U12: 1.4291379 | V12: 3.5220529 | W12: 3.1788853 | X12: 4.4144916 | Y12: 5.7938513
A13: Popayán | B13: 2019 | C13: 6.0943332 | D13: 0.4336121 | E13: 6.0244227 | F13: 6.5637441 | G13: 4.779028 | H13: 6.7955678 | I13: 5.5734261 | J13: 5.170478 | K13: 5.8464907 | L13: 5.3127593 | M13: 1.9045628 | N13: 0 | O13: 3.7635783 | P13: 10 | Q13: 2.9540946 | R13: 3.7244471 | S13: 3.025258 | T13: 0 | U13: 0.44848184 | V13: 1.2804905 | W13: 1.1885576 | X13: 2.4565024 | Y13: 5.4864608
... A193: Leticia | B193: 2024 | C193: 0.32914829 | D193: 0.19056139 | E193: 2.2027723 | F193: 1.3036595 | G193: 1.0065354 | H193: 0.43126688 | I193: 0.056227109 | J193: 2.2159192 | K193: 0.90113772 | L193: 0.95383653 | M193: 4.1404781 | N193: 0 | O193: 3.3221961 | P193: 4.0807175 | Q193: 10 | R193: 4.3086783 | S193: 0 | T193: 0 | U193: 0 | V193: 0.22007991 | W193: 0.055019977 | X193: 2.1818492 | Y193: 3.1063371

Sheet Valor_original (winzo-imp)
A1: Ciudad o AM | B1: Año | C1: TIC-1-1 | D1: TIC-1-2 | E1: TIC-1-3 | F1: TIC-1-4 | G1: TIC-2-1 | H1: TIC-2-2 | I1: TIC-2-3 | J1: INN-1-1 | K1: INN-1-2 | L1: INN-1-3 | M1: INN-1-4 | N1: INN-1-5 | O1: INN-2-1 | P1: INN-2-2 | Q1: INN-2-3 | R1: INN-2-4
A2: Arauca | B2: 2019 | C2: 7.99 | D2: 5.5890582 | E2: 22.427528 | F2: 68.294633 | G2: 1312.722 | H2: 368.053 | I2: 0.5 | J2: 0 | K2: 0 | L2: 11.68429 | M2: 0 | N2: 0 | O2: 0 | P2: 0 | Q2: 0 | R2: 93.474324
A3: Armenia | B3: 2019 | C3: 24.6 | D3: 8.7742677 | E3: 41.797892 | F3: 74.634168 | G3: 10558.9 | H3: 1157.081 | I3: 1.2105 | J3: 2.3712095 | K3: 0 | L3: 430.20514 | M3: 1.61 | N3: 25 | O3: 20.324652 | P3: 13.549768 | Q3: 16.93721 | R3: 752.01214
A4: Barranquilla AM | B4: 2019 | C4: 13.838173 | D4: 11.521319 | E4: 44.982809 | F4: 77.643446 | G4: 7585.936 | H4: 907.957 | I4: 2.2895 | J4: 5.5238914 | K4: 0.60762805 | L4: 475.60705 | M4: 1.63 | N4: 21.6 | O4: 11.047783 | P4: 3.866724 | Q4: 3.3143348 | R4: 1083.7875
A5: Bogotá D.C. | B5: 2019 | C5: 25.31 | D5: 12.107394 | E5: 63.897082 | F5: 87.173928 | G5: 10166.292 | H5: 1601.455 | I5: 2.7656 | J5: 6.043791 | K5: 1.5109478 | L5: 588.46019 | M5: 2.14 | N5: 18.8 | O5: 29.544425 | P5: 18.347223 | Q5: 38.448224 | R5: 3325.0294
A6: Bucaramanga AM | B6: 2019 | C6: 21.283309 | D6: 9.425301 | E6: 50.178464 | F6: 80.175522 | G6: 9643.108 | H6: 1428.933 | I6: 2.6667 | J6: 5.0660539 | K6: 0.83050063 | L6: 522.3849 | M6: 1.36 | N6: 22.6 | O6: 14.118511 | P6: 6.6440051 | Q6: 14.949011 | R6: 1073.0068
A7: Cali AM | B7: 2019 | C7: 21.094539 | D7: 10.080154 | E7: 50.949048 | F7: 82.960341 | G7: 6283.943 | H7: 953.934 | I7: 1.8246 | J7: 5.610336 | K7: 0.5567509 | L7: 431.69609 | M7: 1.51 | N7: 22.98 | O7: 16.702527 | P7: 10.278478 | Q7: 13.276368 | R7: 1997.4509
A8: Cartagena | B8: 2019 | C8: 15.48 | D8: 9.9948442 | E8: 30.987781 | F8: 66.898285 | G8: 4942.26 | H8: 941.383 | I8: 1.5897 | J8: 3.9052665 | K8: 0.51385085 | L8: 350.44628 | M8: 0 | N8: 23.88 | O8: 2.0554034 | P8: 1.0277017 | Q8: 8.2216136 | R8: 612.51021
A9: Cúcuta AM | B9: 2019 | C9: 13.068041 | D9: 8.837763 | E9: 39.469189 | F9: 74.579021 | G9: 5727.211 | H9: 952.619 | I9: 1.7391 | J9: 0.86071668 | K9: 0.32276875 | L9: 145.24594 | M9: 1.12 | N9: 29.79 | O9: 2.1517917 | P9: 5.3794792 | Q9: 4.3035834 | R9: 568.07301
A10: Florencia | B10: 2019 | C10: 11.36 | D10: 6.1853125 | E10: 32.606844 | F10: 67.634542 | G10: 4545.18 | H10: 513.068 | I10: 2.4286 | J10: 0 | K10: 0 | L10: 279.18691 | M10: 1.4 | N10: 15.16 | O10: 5.9401471 | P10: 0 | Q10: 0 | R10: 160.38397
A11: Ibagué | B11: 2019 | C11: 20.75 | D11: 8.5610762 | E11: 43.924345 | F11: 78.468172 | G11: 9662.736 | H11: 2225.139 | I11: 1.8571 | J11: 2.076902 | K11: 0 | L11: 303.98293 | M11: 1.64 | N11: 24.9 | O11: 5.6642782 | P11: 3.7761855 | Q11: 15.104742 | R11: 745.79663
A12: Inírida | B12: 2019 | C12: 2.72 | D12: 1.1109908 | E12: 22.482312 | F12: 49.375557 | G12: 3212.496 | H12: 265.252 | I12: 2.6667 | J12: 0 | K12: 0 | L12: 0 | M12: 0 | N12: 0 | O12: 0 | P12: 0 | Q12: 0 | R12: 0
A13: Leticia | B13: 2019 | C13: 1.78 | D13: 1.7913721 | E13: 16.252225 | F13: 44.746427 | G13: 691.81 | H13: 66.949 | I13: 0.5556 | J13: 8.3084081 | K13: 0 | L13: 373.87836 | M13: 1.22 | N13: 63.64 | O13: 0 | P13: 0 | Q13: 0 | R13: 415.42041
... A193: Yopal | B193: 2024 | C193: 20.3 | D193: 113.29626 | E193: 27.5 | F193: 83 | G193: 5910.632 | H193: 998.459 | I193: 0.7222 | J193: 0.53204507 | K193: 0 | L193: 111.72947 | M193: 0 | N193: 0 | O193: 0 | P193: 5.2319589 | Q193: 57.551548 | R193: 690.61857

Sheet Valor_ranking
A1: Ciudad o AM | B1: Año | C1: =Valor_normalizado!C1 -> TIC-1-1 | D1: =Valor_normalizado!D1 -> TIC-1-2 | E1: =Valor_normalizado!E1 -> TIC-1-3 | F1: =Valor_normalizado!F1 -> TIC-1-4 | G1: =Valor_normalizado!G1 -> TIC-1 | H1: =Valor_normalizado!H1 -> TIC-2-1 | I1: =Valor_normalizado!I1 -> TIC-2-2 | J1: =Valor_normalizado!J1 -> TIC-2-3 | ... Y1: =Valor_normalizado!Y1 -> Puntaje general
A2: Arauca | B2: 2019 | C2: =IF(Valor_normalizado!C2=0,32,IFERROR(RANK(Valor_normalizado!C2,Valor_normalizado!C$2:C$33,0),"NA")) -> 1 | D2: =IF(Valor_normalizado!D2=0,32,IFERROR(RANK(Valor_normalizado!D2,Valor_normalizado!D$2:D$33,0),"NA")) -> 1 | E2: =IF(Valor_normalizado!E2=0,32,IFERROR(RANK(Valor_normalizado!E2,Valor_normalizado!E$2:E$33,0),"NA")) -> 1 | F2: =IF(Valor_normalizado!F2=0,32,IFERROR(RANK(Valor_normalizado!F2,Valor_normalizado!F$2:F$33,0),"NA")) -> 1 | G2: =IF(Valor_normalizado!G2=0,32,IFERROR(RANK(Valor_normalizado!G2,Valor_normalizado!G$2:G$33,0),"NA")) -> 1 | H2: =IF(Valor_normalizado!H2=0,32,IFERROR(RANK(Valor_normalizado!H2,Valor_normalizado!H$2:H$33,0),"NA")) -> 6 | I2: =IF(Valor_normalizado!I2=0,32,IFERROR(RANK(Valor_normalizado!I2,Valor_normalizado!I$2:I$33,0),"NA")) -> 6 | J2: =IF(Valor_normalizado!J2=0,32,IFERROR(RANK(Valor_normalizado!J2,Valor_normalizado!J$2:J$33,0),"NA")) -> 3 | ... Y2: =IF(Valor_normalizado!Y2=0,32,IFERROR(RANK(Valor_normalizado!Y2,Valor_normalizado!Y$2:Y$33,0),"NA")) -> 1
A3: Armenia | B3: 2019 | C3: =IF(Valor_normalizado!C3=0,32,IFERROR(RANK(Valor_normalizado!C3,Valor_normalizado!C$2:C$33,0),"NA")) -> 2 | D3: =IF(Valor_normalizado!D3=0,32,IFERROR(RANK(Valor_normalizado!D3,Valor_normalizado!D$2:D$33,0),"NA")) -> 12 | E3: =IF(Valor_normalizado!E3=0,32,IFERROR(RANK(Valor_normalizado!E3,Valor_normalizado!E$2:E$33,0),"NA")) -> 14 | F3: =IF(Valor_normalizado!F3=0,32,IFERROR(RANK(Valor_normalizado!F3,Valor_normalizado!F$2:F$33,0),"NA")) -> 14 | G3: =IF(Valor_normalizado!G3=0,32,IFERROR(RANK(Valor_normalizado!G3,Valor_normalizado!G$2:G$33,0),"NA")) -> 8 | H3: =IF(Valor_normalizado!H3=0,32,IFERROR(RANK(Valor_normalizado!H3,Valor_normalizado!H$2:H$33,0),"NA")) -> 5 | I3: =IF(Valor_normalizado!I3=0,32,IFERROR(RANK(Valor_normalizado!I3,Valor_normalizado!I$2:I$33,0),"NA")) -> 12 | J3: =IF(Valor_normalizado!J3=0,32,IFERROR(RANK(Valor_normalizado!J3,Valor_normalizado!J$2:J$33,0),"NA")) -> 21 | ... Y3: =IF(Valor_normalizado!Y3=0,32,IFERROR(RANK(Valor_normalizado!Y3,Valor_normalizado!Y$2:Y$33,0),"NA")) -> 12
A4: Barranquilla AM | B4: 2019 | C4: =IF(Valor_normalizado!C4=0,32,IFERROR(RANK(Valor_normalizado!C4,Valor_normalizado!C$2:C$33,0),"NA")) -> 3 | D4: =IF(Valor_normalizado!D4=0,32,IFERROR(RANK(Valor_normalizado!D4,Valor_normalizado!D$2:D$33,0),"NA")) -> 3 | E4: =IF(Valor_normalizado!E4=0,32,IFERROR(RANK(Valor_normalizado!E4,Valor_normalizado!E$2:E$33,0),"NA")) -> 5 | F4: =IF(Valor_normalizado!F4=0,32,IFERROR(RANK(Valor_normalizado!F4,Valor_normalizado!F$2:F$33,0),"NA")) -> 8 | G4: =IF(Valor_normalizado!G4=0,32,IFERROR(RANK(Valor_normalizado!G4,Valor_normalizado!G$2:G$33,0),"NA")) -> 4 | H4: =IF(Valor_normalizado!H4=0,32,IFERROR(RANK(Valor_normalizado!H4,Valor_normalizado!H$2:H$33,0),"NA")) -> 9 | I4: =IF(Valor_normalizado!I4=0,32,IFERROR(RANK(Valor_normalizado!I4,Valor_normalizado!I$2:I$33,0),"NA")) -> 10 | J4: =IF(Valor_normalizado!J4=0,32,IFERROR(RANK(Valor_normalizado!J4,Valor_normalizado!J$2:J$33,0),"NA")) -> 7 | ... Y4: =IF(Valor_normalizado!Y4=0,32,IFERROR(RANK(Valor_normalizado!Y4,Valor_normalizado!Y$2:Y$33,0),"NA")) -> 2
A5: Bogotá D.C. | B5: 2019 | C5: =IF(Valor_normalizado!C5=0,32,IFERROR(RANK(Valor_normalizado!C5,Valor_normalizado!C$2:C$33,0),"NA")) -> 4 | D5: =IF(Valor_normalizado!D5=0,32,IFERROR(RANK(Valor_normalizado!D5,Valor_normalizado!D$2:D$33,0),"NA")) -> 17 | E5: =IF(Valor_normalizado!E5=0,32,IFERROR(RANK(Valor_normalizado!E5,Valor_normalizado!E$2:E$33,0),"NA")) -> 7 | F5: =IF(Valor_normalizado!F5=0,32,IFERROR(RANK(Valor_normalizado!F5,Valor_normalizado!F$2:F$33,0),"NA")) -> 11 | G5: =IF(Valor_normalizado!G5=0,32,IFERROR(RANK(Valor_normalizado!G5,Valor_normalizado!G$2:G$33,0),"NA")) -> 6 | H5: =IF(Valor_normalizado!H5=0,32,IFERROR(RANK(Valor_normalizado!H5,Valor_normalizado!H$2:H$33,0),"NA")) -> 1 | I5: =IF(Valor_normalizado!I5=0,32,IFERROR(RANK(Valor_normalizado!I5,Valor_normalizado!I$2:I$33,0),"NA")) -> 1 | J5: =IF(Valor_normalizado!J5=0,32,IFERROR(RANK(Valor_normalizado!J5,Valor_normalizado!J$2:J$33,0),"NA")) -> 2 | ... Y5: =IF(Valor_normalizado!Y5=0,32,IFERROR(RANK(Valor_normalizado!Y5,Valor_normalizado!Y$2:Y$33,0),"NA")) -> 3
A6: Bucaramanga AM | B6: 2019 | C6: =IF(Valor_normalizado!C6=0,32,IFERROR(RANK(Valor_normalizado!C6,Valor_normalizado!C$2:C$33,0),"NA")) -> 5 | D6: =IF(Valor_normalizado!D6=0,32,IFERROR(RANK(Valor_normalizado!D6,Valor_normalizado!D$2:D$33,0),"NA")) -> 8 | E6: =IF(Valor_normalizado!E6=0,32,IFERROR(RANK(Valor_normalizado!E6,Valor_normalizado!E$2:E$33,0),"NA")) -> 2 | F6: =IF(Valor_normalizado!F6=0,32,IFERROR(RANK(Valor_normalizado!F6,Valor_normalizado!F$2:F$33,0),"NA")) -> 2 | G6: =IF(Valor_normalizado!G6=0,32,IFERROR(RANK(Valor_normalizado!G6,Valor_normalizado!G$2:G$33,0),"NA")) -> 2 | H6: =IF(Valor_normalizado!H6=0,32,IFERROR(RANK(Valor_normalizado!H6,Valor_normalizado!H$2:H$33,0),"NA")) -> 3 | I6: =IF(Valor_normalizado!I6=0,32,IFERROR(RANK(Valor_normalizado!I6,Valor_normalizado!I$2:I$33,0),"NA")) -> 5 | J6: =IF(Valor_normalizado!J6=0,32,IFERROR(RANK(Valor_normalizado!J6,Valor_normalizado!J$2:J$33,0),"NA")) -> 15 | ... Y6: =IF(Valor_normalizado!Y6=0,32,IFERROR(RANK(Valor_normalizado!Y6,Valor_normalizado!Y$2:Y$33,0),"NA")) -> 7
A7: Cali AM | B7: 2019 | C7: =IF(Valor_normalizado!C7=0,32,IFERROR(RANK(Valor_normalizado!C7,Valor_normalizado!C$2:C$33,0),"NA")) -> 6 | D7: =IF(Valor_normalizado!D7=0,32,IFERROR(RANK(Valor_normalizado!D7,Valor_normalizado!D$2:D$33,0),"NA")) -> 7 | E7: =IF(Valor_normalizado!E7=0,32,IFERROR(RANK(Valor_normalizado!E7,Valor_normalizado!E$2:E$33,0),"NA")) -> 4 | F7: =IF(Valor_normalizado!F7=0,32,IFERROR(RANK(Valor_normalizado!F7,Valor_normalizado!F$2:F$33,0),"NA")) -> 5 | G7: =IF(Valor_normalizado!G7=0,32,IFERROR(RANK(Valor_normalizado!G7,Valor_normalizado!G$2:G$33,0),"NA")) -> 5 | H7: =IF(Valor_normalizado!H7=0,32,IFERROR(RANK(Valor_normalizado!H7,Valor_normalizado!H$2:H$33,0),"NA")) -> 8 | I7: =IF(Valor_normalizado!I7=0,32,IFERROR(RANK(Valor_normalizado!I7,Valor_normalizado!I$2:I$33,0),"NA")) -> 7 | J7: =IF(Valor_normalizado!J7=0,32,IFERROR(RANK(Valor_normalizado!J7,Valor_normalizado!J$2:J$33,0),"NA")) -> 4 | ... Y7: =IF(Valor_normalizado!Y7=0,32,IFERROR(RANK(Valor_normalizado!Y7,Valor_normalizado!Y$2:Y$33,0),"NA")) -> 5
A8: Cartagena | B8: 2019 | C8: =IF(Valor_normalizado!C8=0,32,IFERROR(RANK(Valor_normalizado!C8,Valor_normalizado!C$2:C$33,0),"NA")) -> 7 | D8: =IF(Valor_normalizado!D8=0,32,IFERROR(RANK(Valor_normalizado!D8,Valor_normalizado!D$2:D$33,0),"NA")) -> 4 | E8: =IF(Valor_normalizado!E8=0,32,IFERROR(RANK(Valor_normalizado!E8,Valor_normalizado!E$2:E$33,0),"NA")) -> 3 | F8: =IF(Valor_normalizado!F8=0,32,IFERROR(RANK(Valor_normalizado!F8,Valor_normalizado!F$2:F$33,0),"NA")) -> 3 | G8: =IF(Valor_normalizado!G8=0,32,IFERROR(RANK(Valor_normalizado!G8,Valor_normalizado!G$2:G$33,0),"NA")) -> 3 | H8: =IF(Valor_normalizado!H8=0,32,IFERROR(RANK(Valor_normalizado!H8,Valor_normalizado!H$2:H$33,0),"NA")) -> 17 | I8: =IF(Valor_normalizado!I8=0,32,IFERROR(RANK(Valor_normalizado!I8,Valor_normalizado!I$2:I$33,0),"NA")) -> 13 | J8: =IF(Valor_normalizado!J8=0,32,IFERROR(RANK(Valor_normalizado!J8,Valor_normalizado!J$2:J$33,0),"NA")) -> 11 | ... Y8: =IF(Valor_normalizado!Y8=0,32,IFERROR(RANK(Valor_normalizado!Y8,Valor_normalizado!Y$2:Y$33,0),"NA")) -> 4
A9: Cúcuta AM | B9: 2019 | C9: =IF(Valor_normalizado!C9=0,32,IFERROR(RANK(Valor_normalizado!C9,Valor_normalizado!C$2:C$33,0),"NA")) -> 8 | D9: =IF(Valor_normalizado!D9=0,32,IFERROR(RANK(Valor_normalizado!D9,Valor_normalizado!D$2:D$33,0),"NA")) -> 22 | E9: =IF(Valor_normalizado!E9=0,32,IFERROR(RANK(Valor_normalizado!E9,Valor_normalizado!E$2:E$33,0),"NA")) -> 15 | F9: =IF(Valor_normalizado!F9=0,32,IFERROR(RANK(Valor_normalizado!F9,Valor_normalizado!F$2:F$33,0),"NA")) -> 13 | G9: =IF(Valor_normalizado!G9=0,32,IFERROR(RANK(Valor_normalizado!G9,Valor_normalizado!G$2:G$33,0),"NA")) -> 11 | H9: =IF(Valor_normalizado!H9=0,32,IFERROR(RANK(Valor_normalizado!H9,Valor_normalizado!H$2:H$33,0),"NA")) -> 11 | I9: =IF(Valor_normalizado!I9=0,32,IFERROR(RANK(Valor_normalizado!I9,Valor_normalizado!I$2:I$33,0),"NA")) -> 11 | J9: =IF(Valor_normalizado!J9=0,32,IFERROR(RANK(Valor_normalizado!J9,Valor_normalizado!J$2:J$33,0),"NA")) -> 23 | ... Y9: =IF(Valor_normalizado!Y9=0,32,IFERROR(RANK(Valor_normalizado!Y9,Valor_normalizado!Y$2:Y$33,0),"NA")) -> 14
A10: Florencia | B10: 2019 | C10: =IF(Valor_normalizado!C10=0,32,IFERROR(RANK(Valor_normalizado!C10,Valor_normalizado!C$2:C$33,0),"NA")) -> 9 | D10: =IF(Valor_normalizado!D10=0,32,IFERROR(RANK(Valor_normalizado!D10,Valor_normalizado!D$2:D$33,0),"NA")) -> 13 | E10: =IF(Valor_normalizado!E10=0,32,IFERROR(RANK(Valor_normalizado!E10,Valor_normalizado!E$2:E$33,0),"NA")) -> 10 | F10: =IF(Valor_normalizado!F10=0,32,IFERROR(RANK(Valor_normalizado!F10,Valor_normalizado!F$2:F$33,0),"NA")) -> 6 | G10: =IF(Valor_normalizado!G10=0,32,IFERROR(RANK(Valor_normalizado!G10,Valor_normalizado!G$2:G$33,0),"NA")) -> 9 | H10: =IF(Valor_normalizado!H10=0,32,IFERROR(RANK(Valor_normalizado!H10,Valor_normalizado!H$2:H$33,0),"NA")) -> 7 | I10: =IF(Valor_normalizado!I10=0,32,IFERROR(RANK(Valor_normalizado!I10,Valor_normalizado!I$2:I$33,0),"NA")) -> 2 | J10: =IF(Valor_normalizado!J10=0,32,IFERROR(RANK(Valor_normalizado!J10,Valor_normalizado!J$2:J$33,0),"NA")) -> 10 | ... Y10: =IF(Valor_normalizado!Y10=0,32,IFERROR(RANK(Valor_normalizado!Y10,Valor_normalizado!Y$2:Y$33,0),"NA")) -> 11
A11: Ibagué | B11: 2019 | C11: =IF(Valor_normalizado!C11=0,32,IFERROR(RANK(Valor_normalizado!C11,Valor_normalizado!C$2:C$33,0),"NA")) -> 10 | D11: =IF(Valor_normalizado!D11=0,32,IFERROR(RANK(Valor_normalizado!D11,Valor_normalizado!D$2:D$33,0),"NA")) -> 19 | E11: =IF(Valor_normalizado!E11=0,32,IFERROR(RANK(Valor_normalizado!E11,Valor_normalizado!E$2:E$33,0),"NA")) -> 12 | F11: =IF(Valor_normalizado!F11=0,32,IFERROR(RANK(Valor_normalizado!F11,Valor_normalizado!F$2:F$33,0),"NA")) -> 17 | G11: =IF(Valor_normalizado!G11=0,32,IFERROR(RANK(Valor_normalizado!G11,Valor_normalizado!G$2:G$33,0),"NA")) -> 13 | H11: =IF(Valor_normalizado!H11=0,32,IFERROR(RANK(Valor_normalizado!H11,Valor_normalizado!H$2:H$33,0),"NA")) -> 10 | I11: =IF(Valor_normalizado!I11=0,32,IFERROR(RANK(Valor_normalizado!I11,Valor_normalizado!I$2:I$33,0),"NA")) -> 8 | J11: =IF(Valor_normalizado!J11=0,32,IFERROR(RANK(Valor_normalizado!J11,Valor_normalizado!J$2:J$33,0),"NA")) -> 19 | ... Y11: =IF(Valor_normalizado!Y11=0,32,IFERROR(RANK(Valor_normalizado!Y11,Valor_normalizado!Y$2:Y$33,0),"NA")) -> 13
A12: Inírida | B12: 2019 | C12: =IF(Valor_normalizado!C12=0,32,IFERROR(RANK(Valor_normalizado!C12,Valor_normalizado!C$2:C$33,0),"NA")) -> 11 | D12: =IF(Valor_normalizado!D12=0,32,IFERROR(RANK(Valor_normalizado!D12,Valor_normalizado!D$2:D$33,0),"NA")) -> 16 | E12: =IF(Valor_normalizado!E12=0,32,IFERROR(RANK(Valor_normalizado!E12,Valor_normalizado!E$2:E$33,0),"NA")) -> 6 | F12: =IF(Valor_normalizado!F12=0,32,IFERROR(RANK(Valor_normalizado!F12,Valor_normalizado!F$2:F$33,0),"NA")) -> 10 | G12: =IF(Valor_normalizado!G12=0,32,IFERROR(RANK(Valor_normalizado!G12,Valor_normalizado!G$2:G$33,0),"NA")) -> 7 | H12: =IF(Valor_normalizado!H12=0,32,IFERROR(RANK(Valor_normalizado!H12,Valor_normalizado!H$2:H$33,0),"NA")) -> 4 | I12: =IF(Valor_normalizado!I12=0,32,IFERROR(RANK(Valor_normalizado!I12,Valor_normalizado!I$2:I$33,0),"NA")) -> 3 | J12: =IF(Valor_normalizado!J12=0,32,IFERROR(RANK(Valor_normalizado!J12,Valor_normalizado!J$2:J$33,0),"NA")) -> 1 | ... Y12: =IF(Valor_normalizado!Y12=0,32,IFERROR(RANK(Valor_normalizado!Y12,Valor_normalizado!Y$2:Y$33,0),"NA")) -> 6
A13: Leticia | B13: 2019 | C13: =IF(Valor_normalizado!C13=0,32,IFERROR(RANK(Valor_normalizado!C13,Valor_normalizado!C$2:C$33,0),"NA")) -> 12 | D13: =IF(Valor_normalizado!D13=0,32,IFERROR(RANK(Valor_normalizado!D13,Valor_normalizado!D$2:D$33,0),"NA")) -> 15 | E13: =IF(Valor_normalizado!E13=0,32,IFERROR(RANK(Valor_normalizado!E13,Valor_normalizado!E$2:E$33,0),"NA")) -> 9 | F13: =IF(Valor_normalizado!F13=0,32,IFERROR(RANK(Valor_normalizado!F13,Valor_normalizado!F$2:F$33,0),"NA")) -> 16 | G13: =IF(Valor_normalizado!G13=0,32,IFERROR(RANK(Valor_normalizado!G13,Valor_normalizado!G$2:G$33,0),"NA")) -> 12 | H13: =IF(Valor_normalizado!H13=0,32,IFERROR(RANK(Valor_normalizado!H13,Valor_normalizado!H$2:H$33,0),"NA")) -> 2 | I13: =IF(Valor_normalizado!I13=0,32,IFERROR(RANK(Valor_normalizado!I13,Valor_normalizado!I$2:I$33,0),"NA")) -> 4 | J13: =IF(Valor_normalizado!J13=0,32,IFERROR(RANK(Valor_normalizado!J13,Valor_normalizado!J$2:J$33,0),"NA")) -> 12 | ... Y13: =IF(Valor_normalizado!Y13=0,32,IFERROR(RANK(Valor_normalizado!Y13,Valor_normalizado!Y$2:Y$33,0),"NA")) -> 9
... A33: Yopal | B33: 2019 | C33: =IF(Valor_normalizado!C33=0,32,IFERROR(RANK(Valor_normalizado!C33,Valor_normalizado!C$2:C$33,0),"NA")) -> 32 | D33: =IF(Valor_normalizado!D33=0,32,IFERROR(RANK(Valor_normalizado!D33,Valor_normalizado!D$2:D$33,0),"NA")) -> 28 | E33: =IF(Valor_normalizado!E33=0,32,IFERROR(RANK(Valor_normalizado!E33,Valor_normalizado!E$2:E$33,0),"NA")) -> 24 | F33: =IF(Valor_normalizado!F33=0,32,IFERROR(RANK(Valor_normalizado!F33,Valor_normalizado!F$2:F$33,0),"NA")) -> 32 | G33: =IF(Valor_normalizado!G33=0,32,IFERROR(RANK(Valor_normalizado!G33,Valor_normalizado!G$2:G$33,0),"NA")) -> 31 | H33: =IF(Valor_normalizado!H33=0,32,IFERROR(RANK(Valor_normalizado!H33,Valor_normalizado!H$2:H$33,0),"NA")) -> 32 | I33: =IF(Valor_normalizado!I33=0,32,IFERROR(RANK(Valor_normalizado!I33,Valor_normalizado!I$2:I$33,0),"NA")) -> 32 | J33: =IF(Valor_normalizado!J33=0,32,IFERROR(RANK(Valor_normalizado!J33,Valor_normalizado!J$2:J$33,0),"NA")) -> 32 | ... Y33: =IF(Valor_normalizado!Y33=0,32,IFERROR(RANK(Valor_normalizado!Y33,Valor_normalizado!Y$2:Y$33,0),"NA")) -> 32
A34: Arauca | B34: 2020 | C34: =IF(Valor_normalizado!C34=0,32,IFERROR(RANK(Valor_normalizado!C34,Valor_normalizado!C$34:C$65,0),"NA")) -> 25 | D34: =IF(Valor_normalizado!D34=0,32,IFERROR(RANK(Valor_normalizado!D34,Valor_normalizado!D$34:D$65,0),"NA")) -> 25 | E34: =IF(Valor_normalizado!E34=0,32,IFERROR(RANK(Valor_normalizado!E34,Valor_normalizado!E$34:E$65,0),"NA")) -> 30 | F34: =IF(Valor_normalizado!F34=0,32,IFERROR(RANK(Valor_normalizado!F34,Valor_normalizado!F$34:F$65,0),"NA")) -> 20 | G34: =IF(Valor_normalizado!G34=0,32,IFERROR(RANK(Valor_normalizado!G34,Valor_normalizado!G$34:G$65,0),"NA")) -> 27 | H34: =IF(Valor_normalizado!H34=0,32,IFERROR(RANK(Valor_normalizado!H34,Valor_normalizado!H$34:H$65,0),"NA")) -> 30 | I34: =IF(Valor_normalizado!I34=0,32,IFERROR(RANK(Valor_normalizado!I34,Valor_normalizado!I$34:I$65,0),"NA")) -> 26 | J34: =IF(Valor_normalizado!J34=0,32,IFERROR(RANK(Valor_normalizado!J34,Valor_normalizado!J$34:J$65,0),"NA")) -> 31 | ... Y34: =IF(Valor_normalizado!Y34=0,32,IFERROR(RANK(Valor_normalizado!Y34,Valor_normalizado!Y$34:Y$65,0),"NA")) -> 27
A35: Armenia | B35: 2020 | C35: =IF(Valor_normalizado!C35=0,32,IFERROR(RANK(Valor_normalizado!C35,Valor_normalizado!C$34:C$65,0),"NA")) -> 2 | D35: =IF(Valor_normalizado!D35=0,32,IFERROR(RANK(Valor_normalizado!D35,Valor_normalizado!D$34:D$65,0),"NA")) -> 20 | E35: =IF(Valor_normalizado!E35=0,32,IFERROR(RANK(Valor_normalizado!E35,Valor_normalizado!E$34:E$65,0),"NA")) -> 14 | F35: =IF(Valor_normalizado!F35=0,32,IFERROR(RANK(Valor_normalizado!F35,Valor_normalizado!F$34:F$65,0),"NA")) -> 14 | G35: =IF(Valor_normalizado!G35=0,32,IFERROR(RANK(Valor_normalizado!G35,Valor_normalizado!G$34:G$65,0),"NA")) -> 9 | H35: =IF(Valor_normalizado!H35=0,32,IFERROR(RANK(Valor_normalizado!H35,Valor_normalizado!H$34:H$65,0),"NA")) -> 4 | I35: =IF(Valor_normalizado!I35=0,32,IFERROR(RANK(Valor_normalizado!I35,Valor_normalizado!I$34:I$65,0),"NA")) -> 10 | J35: =IF(Valor_normalizado!J35=0,32,IFERROR(RANK(Valor_normalizado!J35,Valor_normalizado!J$34:J$65,0),"NA")) -> 20 | ... Y35: =IF(Valor_normalizado!Y35=0,32,IFERROR(RANK(Valor_normalizado!Y35,Valor_normalizado!Y$34:Y$65,0),"NA")) -> 10
A36: Barranquilla AM | B36: 2020 | C36: =IF(Valor_normalizado!C36=0,32,IFERROR(RANK(Valor_normalizado!C36,Valor_normalizado!C$34:C$65,0),"NA")) -> 14 | D36: =IF(Valor_normalizado!D36=0,32,IFERROR(RANK(Valor_normalizado!D36,Valor_normalizado!D$34:D$65,0),"NA")) -> 3 | E36: =IF(Valor_normalizado!E36=0,32,IFERROR(RANK(Valor_normalizado!E36,Valor_normalizado!E$34:E$65,0),"NA")) -> 8 | F36: =IF(Valor_normalizado!F36=0,32,IFERROR(RANK(Valor_normalizado!F36,Valor_normalizado!F$34:F$65,0),"NA")) -> 7 | G36: =IF(Valor_normalizado!G36=0,32,IFERROR(RANK(Valor_normalizado!G36,Valor_normalizado!G$34:G$65,0),"NA")) -> 11 | H36: =IF(Valor_normalizado!H36=0,32,IFERROR(RANK(Valor_normalizado!H36,Valor_normalizado!H$34:H$65,0),"NA")) -> 13 | I36: =IF(Valor_normalizado!I36=0,32,IFERROR(RANK(Valor_normalizado!I36,Valor_normalizado!I$34:I$65,0),"NA")) -> 12 | J36: =IF(Valor_normalizado!J36=0,32,IFERROR(RANK(Valor_normalizado!J36,Valor_normalizado!J$34:J$65,0),"NA")) -> 6 | ... Y36: =IF(Valor_normalizado!Y36=0,32,IFERROR(RANK(Valor_normalizado!Y36,Valor_normalizado!Y$34:Y$65,0),"NA")) -> 8
A37: Bogotá D.C. | B37: 2020 | C37: =IF(Valor_normalizado!C37=0,32,IFERROR(RANK(Valor_normalizado!C37,Valor_normalizado!C$34:C$65,0),"NA")) -> 1 | D37: =IF(Valor_normalizado!D37=0,32,IFERROR(RANK(Valor_normalizado!D37,Valor_normalizado!D$34:D$65,0),"NA")) -> 1 | E37: =IF(Valor_normalizado!E37=0,32,IFERROR(RANK(Valor_normalizado!E37,Valor_normalizado!E$34:E$65,0),"NA")) -> 1 | F37: =IF(Valor_normalizado!F37=0,32,IFERROR(RANK(Valor_normalizado!F37,Valor_normalizado!F$34:F$65,0),"NA")) -> 1 | G37: =IF(Valor_normalizado!G37=0,32,IFERROR(RANK(Valor_normalizado!G37,Valor_normalizado!G$34:G$65,0),"NA")) -> 1 | H37: =IF(Valor_normalizado!H37=0,32,IFERROR(RANK(Valor_normalizado!H37,Valor_normalizado!H$34:H$65,0),"NA")) -> 6 | I37: =IF(Valor_normalizado!I37=0,32,IFERROR(RANK(Valor_normalizado!I37,Valor_normalizado!I$34:I$65,0),"NA")) -> 6 | J37: =IF(Valor_normalizado!J37=0,32,IFERROR(RANK(Valor_normalizado!J37,Valor_normalizado!J$34:J$65,0),"NA")) -> 1 | ... Y37: =IF(Valor_normalizado!Y37=0,32,IFERROR(RANK(Valor_normalizado!Y37,Valor_normalizado!Y$34:Y$65,0),"NA")) -> 1
A38: Bucaramanga AM | B38: 2020 | C38: =IF(Valor_normalizado!C38=0,32,IFERROR(RANK(Valor_normalizado!C38,Valor_normalizado!C$34:C$65,0),"NA")) -> 8 | D38: =IF(Valor_normalizado!D38=0,32,IFERROR(RANK(Valor_normalizado!D38,Valor_normalizado!D$34:D$65,0),"NA")) -> 8 | E38: =IF(Valor_normalizado!E38=0,32,IFERROR(RANK(Valor_normalizado!E38,Valor_normalizado!E$34:E$65,0),"NA")) -> 4 | F38: =IF(Valor_normalizado!F38=0,32,IFERROR(RANK(Valor_normalizado!F38,Valor_normalizado!F$34:F$65,0),"NA")) -> 5 | G38: =IF(Valor_normalizado!G38=0,32,IFERROR(RANK(Valor_normalizado!G38,Valor_normalizado!G$34:G$65,0),"NA")) -> 5 | H38: =IF(Valor_normalizado!H38=0,32,IFERROR(RANK(Valor_normalizado!H38,Valor_normalizado!H$34:H$65,0),"NA")) -> 7 | I38: =IF(Valor_normalizado!I38=0,32,IFERROR(RANK(Valor_normalizado!I38,Valor_normalizado!I$34:I$65,0),"NA")) -> 7 | J38: =IF(Valor_normalizado!J38=0,32,IFERROR(RANK(Valor_normalizado!J38,Valor_normalizado!J$34:J$65,0),"NA")) -> 4 | ... Y38: =IF(Valor_normalizado!Y38=0,32,IFERROR(RANK(Valor_normalizado!Y38,Valor_normalizado!Y$34:Y$65,0),"NA")) -> 5
A39: Cali AM | B39: 2020 | C39: =IF(Valor_normalizado!C39=0,32,IFERROR(RANK(Valor_normalizado!C39,Valor_normalizado!C$34:C$65,0),"NA")) -> 6 | D39: =IF(Valor_normalizado!D39=0,32,IFERROR(RANK(Valor_normalizado!D39,Valor_normalizado!D$34:D$65,0),"NA")) -> 4 | E39: =IF(Valor_normalizado!E39=0,32,IFERROR(RANK(Valor_normalizado!E39,Valor_normalizado!E$34:E$65,0),"NA")) -> 3 | F39: =IF(Valor_normalizado!F39=0,32,IFERROR(RANK(Valor_normalizado!F39,Valor_normalizado!F$34:F$65,0),"NA")) -> 3 | G39: =IF(Valor_normalizado!G39=0,32,IFERROR(RANK(Valor_normalizado!G39,Valor_normalizado!G$34:G$65,0),"NA")) -> 3 | H39: =IF(Valor_normalizado!H39=0,32,IFERROR(RANK(Valor_normalizado!H39,Valor_normalizado!H$34:H$65,0),"NA")) -> 17 | I39: =IF(Valor_normalizado!I39=0,32,IFERROR(RANK(Valor_normalizado!I39,Valor_normalizado!I$34:I$65,0),"NA")) -> 14 | J39: =IF(Valor_normalizado!J39=0,32,IFERROR(RANK(Valor_normalizado!J39,Valor_normalizado!J$34:J$65,0),"NA")) -> 11 | ... Y39: =IF(Valor_normalizado!Y39=0,32,IFERROR(RANK(Valor_normalizado!Y39,Valor_normalizado!Y$34:Y$65,0),"NA")) -> 4
A40: Cartagena | B40: 2020 | C40: =IF(Valor_normalizado!C40=0,32,IFERROR(RANK(Valor_normalizado!C40,Valor_normalizado!C$34:C$65,0),"NA")) -> 17 | D40: =IF(Valor_normalizado!D40=0,32,IFERROR(RANK(Valor_normalizado!D40,Valor_normalizado!D$34:D$65,0),"NA")) -> 2 | E40: =IF(Valor_normalizado!E40=0,32,IFERROR(RANK(Valor_normalizado!E40,Valor_normalizado!E$34:E$65,0),"NA")) -> 23 | F40: =IF(Valor_normalizado!F40=0,32,IFERROR(RANK(Valor_normalizado!F40,Valor_normalizado!F$34:F$65,0),"NA")) -> 22 | G40: =IF(Valor_normalizado!G40=0,32,IFERROR(RANK(Valor_normalizado!G40,Valor_normalizado!G$34:G$65,0),"NA")) -> 18 | H40: =IF(Valor_normalizado!H40=0,32,IFERROR(RANK(Valor_normalizado!H40,Valor_normalizado!H$34:H$65,0),"NA")) -> 24 | I40: =IF(Valor_normalizado!I40=0,32,IFERROR(RANK(Valor_normalizado!I40,Valor_normalizado!I$34:I$65,0),"NA")) -> 17 | J40: =IF(Valor_normalizado!J40=0,32,IFERROR(RANK(Valor_normalizado!J40,Valor_normalizado!J$34:J$65,0),"NA")) -> 16 | ... Y40: =IF(Valor_normalizado!Y40=0,32,IFERROR(RANK(Valor_normalizado!Y40,Valor_normalizado!Y$34:Y$65,0),"NA")) -> 11
A41: Cúcuta AM | B41: 2020 | C41: =IF(Valor_normalizado!C41=0,32,IFERROR(RANK(Valor_normalizado!C41,Valor_normalizado!C$34:C$65,0),"NA")) -> 19 | D41: =IF(Valor_normalizado!D41=0,32,IFERROR(RANK(Valor_normalizado!D41,Valor_normalizado!D$34:D$65,0),"NA")) -> 5 | E41: =IF(Valor_normalizado!E41=0,32,IFERROR(RANK(Valor_normalizado!E41,Valor_normalizado!E$34:E$65,0),"NA")) -> 16 | F41: =IF(Valor_normalizado!F41=0,32,IFERROR(RANK(Valor_normalizado!F41,Valor_normalizado!F$34:F$65,0),"NA")) -> 15 | G41: =IF(Valor_normalizado!G41=0,32,IFERROR(RANK(Valor_normalizado!G41,Valor_normalizado!G$34:G$65,0),"NA")) -> 16 | H41: =IF(Valor_normalizado!H41=0,32,IFERROR(RANK(Valor_normalizado!H41,Valor_normalizado!H$34:H$65,0),"NA")) -> 21 | I41: =IF(Valor_normalizado!I41=0,32,IFERROR(RANK(Valor_normalizado!I41,Valor_normalizado!I$34:I$65,0),"NA")) -> 16 | J41: =IF(Valor_normalizado!J41=0,32,IFERROR(RANK(Valor_normalizado!J41,Valor_normalizado!J$34:J$65,0),"NA")) -> 15 | ... Y41: =IF(Valor_normalizado!Y41=0,32,IFERROR(RANK(Valor_normalizado!Y41,Valor_normalizado!Y$34:Y$65,0),"NA")) -> 17
A42: Florencia | B42: 2020 | C42: =IF(Valor_normalizado!C42=0,32,IFERROR(RANK(Valor_normalizado!C42,Valor_normalizado!C$34:C$65,0),"NA")) -> 22 | D42: =IF(Valor_normalizado!D42=0,32,IFERROR(RANK(Valor_normalizado!D42,Valor_normalizado!D$34:D$65,0),"NA")) -> 23 | E42: =IF(Valor_normalizado!E42=0,32,IFERROR(RANK(Valor_normalizado!E42,Valor_normalizado!E$34:E$65,0),"NA")) -> 19 | F42: =IF(Valor_normalizado!F42=0,32,IFERROR(RANK(Valor_normalizado!F42,Valor_normalizado!F$34:F$65,0),"NA")) -> 21 | G42: =IF(Valor_normalizado!G42=0,32,IFERROR(RANK(Valor_normalizado!G42,Valor_normalizado!G$34:G$65,0),"NA")) -> 21 | H42: =IF(Valor_normalizado!H42=0,32,IFERROR(RANK(Valor_normalizado!H42,Valor_normalizado!H$34:H$65,0),"NA")) -> 23 | I42: =IF(Valor_normalizado!I42=0,32,IFERROR(RANK(Valor_normalizado!I42,Valor_normalizado!I$34:I$65,0),"NA")) -> 29 | J42: =IF(Valor_normalizado!J42=0,32,IFERROR(RANK(Valor_normalizado!J42,Valor_normalizado!J$34:J$65,0),"NA")) -> 7 | ... Y42: =IF(Valor_normalizado!Y42=0,32,IFERROR(RANK(Valor_normalizado!Y42,Valor_normalizado!Y$34:Y$65,0),"NA")) -> 23
A43: Ibagué | B43: 2020 | C43: =IF(Valor_normalizado!C43=0,32,IFERROR(RANK(Valor_normalizado!C43,Valor_normalizado!C$34:C$65,0),"NA")) -> 9 | D43: =IF(Valor_normalizado!D43=0,32,IFERROR(RANK(Valor_normalizado!D43,Valor_normalizado!D$34:D$65,0),"NA")) -> 9 | E43: =IF(Valor_normalizado!E43=0,32,IFERROR(RANK(Valor_normalizado!E43,Valor_normalizado!E$34:E$65,0),"NA")) -> 10 | F43: =IF(Valor_normalizado!F43=0,32,IFERROR(RANK(Valor_normalizado!F43,Valor_normalizado!F$34:F$65,0),"NA")) -> 6 | G43: =IF(Valor_normalizado!G43=0,32,IFERROR(RANK(Valor_normalizado!G43,Valor_normalizado!G$34:G$65,0),"NA")) -> 7 | H43: =IF(Valor_normalizado!H43=0,32,IFERROR(RANK(Valor_normalizado!H43,Valor_normalizado!H$34:H$65,0),"NA")) -> 8 | I43: =IF(Valor_normalizado!I43=0,32,IFERROR(RANK(Valor_normalizado!I43,Valor_normalizado!I$34:I$65,0),"NA")) -> 5 | J43: =IF(Valor_normalizado!J43=0,32,IFERROR(RANK(Valor_normalizado!J43,Valor_normalizado!J$34:J$65,0),"NA")) -> 8 | ... Y43: =IF(Valor_normalizado!Y43=0,32,IFERROR(RANK(Valor_normalizado!Y43,Valor_normalizado!Y$34:Y$65,0),"NA")) -> 12
A44: Inírida | B44: 2020 | C44: =IF(Valor_normalizado!C44=0,32,IFERROR(RANK(Valor_normalizado!C44,Valor_normalizado!C$34:C$65,0),"NA")) -> 30 | D44: =IF(Valor_normalizado!D44=0,32,IFERROR(RANK(Valor_normalizado!D44,Valor_normalizado!D$34:D$65,0),"NA")) -> 31 | E44: =IF(Valor_normalizado!E44=0,32,IFERROR(RANK(Valor_normalizado!E44,Valor_normalizado!E$34:E$65,0),"NA")) -> 29 | F44: =IF(Valor_normalizado!F44=0,32,IFERROR(RANK(Valor_normalizado!F44,Valor_normalizado!F$34:F$65,0),"NA")) -> 30 | G44: =IF(Valor_normalizado!G44=0,32,IFERROR(RANK(Valor_normalizado!G44,Valor_normalizado!G$34:G$65,0),"NA")) -> 30 | H44: =IF(Valor_normalizado!H44=0,32,IFERROR(RANK(Valor_normalizado!H44,Valor_normalizado!H$34:H$65,0),"NA")) -> 20 | I44: =IF(Valor_normalizado!I44=0,32,IFERROR(RANK(Valor_normalizado!I44,Valor_normalizado!I$34:I$65,0),"NA")) -> 27 | J44: =IF(Valor_normalizado!J44=0,32,IFERROR(RANK(Valor_normalizado!J44,Valor_normalizado!J$34:J$65,0),"NA")) -> 10 | ... Y44: =IF(Valor_normalizado!Y44=0,32,IFERROR(RANK(Valor_normalizado!Y44,Valor_normalizado!Y$34:Y$65,0),"NA")) -> 32
A45: Leticia | B45: 2020 | C45: =IF(Valor_normalizado!C45=0,32,IFERROR(RANK(Valor_normalizado!C45,Valor_normalizado!C$34:C$65,0),"NA")) -> 31 | D45: =IF(Valor_normalizado!D45=0,32,IFERROR(RANK(Valor_normalizado!D45,Valor_normalizado!D$34:D$65,0),"NA")) -> 29 | E45: =IF(Valor_normalizado!E45=0,32,IFERROR(RANK(Valor_normalizado!E45,Valor_normalizado!E$34:E$65,0),"NA")) -> 32 | F45: =IF(Valor_normalizado!F45=0,32,IFERROR(RANK(Valor_normalizado!F45,Valor_normalizado!F$34:F$65,0),"NA")) -> 31 | G45: =IF(Valor_normalizado!G45=0,32,IFERROR(RANK(Valor_normalizado!G45,Valor_normalizado!G$34:G$65,0),"NA")) -> 32 | H45: =IF(Valor_normalizado!H45=0,32,IFERROR(RANK(Valor_normalizado!H45,Valor_normalizado!H$34:H$65,0),"NA")) -> 31 | I45: =IF(Valor_normalizado!I45=0,32,IFERROR(RANK(Valor_normalizado!I45,Valor_normalizado!I$34:I$65,0),"NA")) -> 31 | J45: =IF(Valor_normalizado!J45=0,32,IFERROR(RANK(Valor_normalizado!J45,Valor_normalizado!J$34:J$65,0),"NA")) -> 28 | ... Y45: =IF(Valor_normalizado!Y45=0,32,IFERROR(RANK(Valor_normalizado!Y45,Valor_normalizado!Y$34:Y$65,0),"NA")) -> 28
... A65: Yopal | B65: 2020 | C65: =IF(Valor_normalizado!C65=0,32,IFERROR(RANK(Valor_normalizado!C65,Valor_normalizado!C$34:C$65,0),"NA")) -> 15 | D65: =IF(Valor_normalizado!D65=0,32,IFERROR(RANK(Valor_normalizado!D65,Valor_normalizado!D$34:D$65,0),"NA")) -> 21 | E65: =IF(Valor_normalizado!E65=0,32,IFERROR(RANK(Valor_normalizado!E65,Valor_normalizado!E$34:E$65,0),"NA")) -> 11 | F65: =IF(Valor_normalizado!F65=0,32,IFERROR(RANK(Valor_normalizado!F65,Valor_normalizado!F$34:F$65,0),"NA")) -> 12 | G65: =IF(Valor_normalizado!G65=0,32,IFERROR(RANK(Valor_normalizado!G65,Valor_normalizado!G$34:G$65,0),"NA")) -> 15 | H65: =IF(Valor_normalizado!H65=0,32,IFERROR(RANK(Valor_normalizado!H65,Valor_normalizado!H$34:H$65,0),"NA")) -> 22 | I65: =IF(Valor_normalizado!I65=0,32,IFERROR(RANK(Valor_normalizado!I65,Valor_normalizado!I$34:I$65,0),"NA")) -> 25 | J65: =IF(Valor_normalizado!J65=0,32,IFERROR(RANK(Valor_normalizado!J65,Valor_normalizado!J$34:J$65,0),"NA")) -> 26 | ... Y65: =IF(Valor_normalizado!Y65=0,32,IFERROR(RANK(Valor_normalizado!Y65,Valor_normalizado!Y$34:Y$65,0),"NA")) -> 21
A66: Arauca | B66: 2021 | C66: =IF(Valor_normalizado!C66=0,32,IFERROR(RANK(Valor_normalizado!C66,Valor_normalizado!C$66:C$97,0),"NA")) -> 25 | D66: =IF(Valor_normalizado!D66=0,32,IFERROR(RANK(Valor_normalizado!D66,Valor_normalizado!D$66:D$97,0),"NA")) -> 25 | E66: =IF(Valor_normalizado!E66=0,32,IFERROR(RANK(Valor_normalizado!E66,Valor_normalizado!E$66:E$97,0),"NA")) -> 30 | F66: =IF(Valor_normalizado!F66=0,32,IFERROR(RANK(Valor_normalizado!F66,Valor_normalizado!F$66:F$97,0),"NA")) -> 20 | G66: =IF(Valor_normalizado!G66=0,32,IFERROR(RANK(Valor_normalizado!G66,Valor_normalizado!G$66:G$97,0),"NA")) -> 27 | H66: =IF(Valor_normalizado!H66=0,32,IFERROR(RANK(Valor_normalizado!H66,Valor_normalizado!H$66:H$97,0),"NA")) -> 31 | I66: =IF(Valor_normalizado!I66=0,32,IFERROR(RANK(Valor_normalizado!I66,Valor_normalizado!I$66:I$97,0),"NA")) -> 29 | J66: =IF(Valor_normalizado!J66=0,32,IFERROR(RANK(Valor_normalizado!J66,Valor_normalizado!J$66:J$97,0),"NA")) -> 31 | ... Y66: =IF(Valor_normalizado!Y66=0,32,IFERROR(RANK(Valor_normalizado!Y66,Valor_normalizado!Y$66:Y$97,0),"NA")) -> 27
A67: Armenia | B67: 2021 | C67: =IF(Valor_normalizado!C67=0,32,IFERROR(RANK(Valor_normalizado!C67,Valor_normalizado!C$66:C$97,0),"NA")) -> 1 | D67: =IF(Valor_normalizado!D67=0,32,IFERROR(RANK(Valor_normalizado!D67,Valor_normalizado!D$66:D$97,0),"NA")) -> 19 | E67: =IF(Valor_normalizado!E67=0,32,IFERROR(RANK(Valor_normalizado!E67,Valor_normalizado!E$66:E$97,0),"NA")) -> 14 | F67: =IF(Valor_normalizado!F67=0,32,IFERROR(RANK(Valor_normalizado!F67,Valor_normalizado!F$66:F$97,0),"NA")) -> 14 | G67: =IF(Valor_normalizado!G67=0,32,IFERROR(RANK(Valor_normalizado!G67,Valor_normalizado!G$66:G$97,0),"NA")) -> 7 | H67: =IF(Valor_normalizado!H67=0,32,IFERROR(RANK(Valor_normalizado!H67,Valor_normalizado!H$66:H$97,0),"NA")) -> 4 | I67: =IF(Valor_normalizado!I67=0,32,IFERROR(RANK(Valor_normalizado!I67,Valor_normalizado!I$66:I$97,0),"NA")) -> 10 | J67: =IF(Valor_normalizado!J67=0,32,IFERROR(RANK(Valor_normalizado!J67,Valor_normalizado!J$66:J$97,0),"NA")) -> 19 | ... Y67: =IF(Valor_normalizado!Y67=0,32,IFERROR(RANK(Valor_normalizado!Y67,Valor_normalizado!Y$66:Y$97,0),"NA")) -> 11
A68: Barranquilla AM | B68: 2021 | C68: =IF(Valor_normalizado!C68=0,32,IFERROR(RANK(Valor_normalizado!C68,Valor_normalizado!C$66:C$97,0),"NA")) -> 15 | D68: =IF(Valor_normalizado!D68=0,32,IFERROR(RANK(Valor_normalizado!D68,Valor_normalizado!D$66:D$97,0),"NA")) -> 5 | E68: =IF(Valor_normalizado!E68=0,32,IFERROR(RANK(Valor_normalizado!E68,Valor_normalizado!E$66:E$97,0),"NA")) -> 8 | F68: =IF(Valor_normalizado!F68=0,32,IFERROR(RANK(Valor_normalizado!F68,Valor_normalizado!F$66:F$97,0),"NA")) -> 7 | G68: =IF(Valor_normalizado!G68=0,32,IFERROR(RANK(Valor_normalizado!G68,Valor_normalizado!G$66:G$97,0),"NA")) -> 12 | H68: =IF(Valor_normalizado!H68=0,32,IFERROR(RANK(Valor_normalizado!H68,Valor_normalizado!H$66:H$97,0),"NA")) -> 15 | I68: =IF(Valor_normalizado!I68=0,32,IFERROR(RANK(Valor_normalizado!I68,Valor_normalizado!I$66:I$97,0),"NA")) -> 11 | J68: =IF(Valor_normalizado!J68=0,32,IFERROR(RANK(Valor_normalizado!J68,Valor_normalizado!J$66:J$97,0),"NA")) -> 8 | ... Y68: =IF(Valor_normalizado!Y68=0,32,IFERROR(RANK(Valor_normalizado!Y68,Valor_normalizado!Y$66:Y$97,0),"NA")) -> 8
A69: Bogotá D.C. | B69: 2021 | C69: =IF(Valor_normalizado!C69=0,32,IFERROR(RANK(Valor_normalizado!C69,Valor_normalizado!C$66:C$97,0),"NA")) -> 2 | D69: =IF(Valor_normalizado!D69=0,32,IFERROR(RANK(Valor_normalizado!D69,Valor_normalizado!D$66:D$97,0),"NA")) -> 1 | E69: =IF(Valor_normalizado!E69=0,32,IFERROR(RANK(Valor_normalizado!E69,Valor_normalizado!E$66:E$97,0),"NA")) -> 1 | F69: =IF(Valor_normalizado!F69=0,32,IFERROR(RANK(Valor_normalizado!F69,Valor_normalizado!F$66:F$97,0),"NA")) -> 1 | G69: =IF(Valor_normalizado!G69=0,32,IFERROR(RANK(Valor_normalizado!G69,Valor_normalizado!G$66:G$97,0),"NA")) -> 1 | H69: =IF(Valor_normalizado!H69=0,32,IFERROR(RANK(Valor_normalizado!H69,Valor_normalizado!H$66:H$97,0),"NA")) -> 7 | I69: =IF(Valor_normalizado!I69=0,32,IFERROR(RANK(Valor_normalizado!I69,Valor_normalizado!I$66:I$97,0),"NA")) -> 4 | J69: =IF(Valor_normalizado!J69=0,32,IFERROR(RANK(Valor_normalizado!J69,Valor_normalizado!J$66:J$97,0),"NA")) -> 3 | ... Y69: =IF(Valor_normalizado!Y69=0,32,IFERROR(RANK(Valor_normalizado!Y69,Valor_normalizado!Y$66:Y$97,0),"NA")) -> 1
A70: Bucaramanga AM | B70: 2021 | C70: =IF(Valor_normalizado!C70=0,32,IFERROR(RANK(Valor_normalizado!C70,Valor_normalizado!C$66:C$97,0),"NA")) -> 8 | D70: =IF(Valor_normalizado!D70=0,32,IFERROR(RANK(Valor_normalizado!D70,Valor_normalizado!D$66:D$97,0),"NA")) -> 6 | E70: =IF(Valor_normalizado!E70=0,32,IFERROR(RANK(Valor_normalizado!E70,Valor_normalizado!E$66:E$97,0),"NA")) -> 4 | F70: =IF(Valor_normalizado!F70=0,32,IFERROR(RANK(Valor_normalizado!F70,Valor_normalizado!F$66:F$97,0),"NA")) -> 5 | G70: =IF(Valor_normalizado!G70=0,32,IFERROR(RANK(Valor_normalizado!G70,Valor_normalizado!G$66:G$97,0),"NA")) -> 5 | H70: =IF(Valor_normalizado!H70=0,32,IFERROR(RANK(Valor_normalizado!H70,Valor_normalizado!H$66:H$97,0),"NA")) -> 8 | I70: =IF(Valor_normalizado!I70=0,32,IFERROR(RANK(Valor_normalizado!I70,Valor_normalizado!I$66:I$97,0),"NA")) -> 6 | J70: =IF(Valor_normalizado!J70=0,32,IFERROR(RANK(Valor_normalizado!J70,Valor_normalizado!J$66:J$97,0),"NA")) -> 5 | ... Y70: =IF(Valor_normalizado!Y70=0,32,IFERROR(RANK(Valor_normalizado!Y70,Valor_normalizado!Y$66:Y$97,0),"NA")) -> 5
A71: Cali AM | B71: 2021 | C71: =IF(Valor_normalizado!C71=0,32,IFERROR(RANK(Valor_normalizado!C71,Valor_normalizado!C$66:C$97,0),"NA")) -> 7 | D71: =IF(Valor_normalizado!D71=0,32,IFERROR(RANK(Valor_normalizado!D71,Valor_normalizado!D$66:D$97,0),"NA")) -> 4 | E71: =IF(Valor_normalizado!E71=0,32,IFERROR(RANK(Valor_normalizado!E71,Valor_normalizado!E$66:E$97,0),"NA")) -> 3 | F71: =IF(Valor_normalizado!F71=0,32,IFERROR(RANK(Valor_normalizado!F71,Valor_normalizado!F$66:F$97,0),"NA")) -> 3 | G71: =IF(Valor_normalizado!G71=0,32,IFERROR(RANK(Valor_normalizado!G71,Valor_normalizado!G$66:G$97,0),"NA")) -> 3 | H71: =IF(Valor_normalizado!H71=0,32,IFERROR(RANK(Valor_normalizado!H71,Valor_normalizado!H$66:H$97,0),"NA")) -> 20 | I71: =IF(Valor_normalizado!I71=0,32,IFERROR(RANK(Valor_normalizado!I71,Valor_normalizado!I$66:I$97,0),"NA")) -> 15 | J71: =IF(Valor_normalizado!J71=0,32,IFERROR(RANK(Valor_normalizado!J71,Valor_normalizado!J$66:J$97,0),"NA")) -> 10 | ... Y71: =IF(Valor_normalizado!Y71=0,32,IFERROR(RANK(Valor_normalizado!Y71,Valor_normalizado!Y$66:Y$97,0),"NA")) -> 4
A72: Cartagena | B72: 2021 | C72: =IF(Valor_normalizado!C72=0,32,IFERROR(RANK(Valor_normalizado!C72,Valor_normalizado!C$66:C$97,0),"NA")) -> 17 | D72: =IF(Valor_normalizado!D72=0,32,IFERROR(RANK(Valor_normalizado!D72,Valor_normalizado!D$66:D$97,0),"NA")) -> 2 | E72: =IF(Valor_normalizado!E72=0,32,IFERROR(RANK(Valor_normalizado!E72,Valor_normalizado!E$66:E$97,0),"NA")) -> 23 | F72: =IF(Valor_normalizado!F72=0,32,IFERROR(RANK(Valor_normalizado!F72,Valor_normalizado!F$66:F$97,0),"NA")) -> 22 | G72: =IF(Valor_normalizado!G72=0,32,IFERROR(RANK(Valor_normalizado!G72,Valor_normalizado!G$66:G$97,0),"NA")) -> 18 | H72: =IF(Valor_normalizado!H72=0,32,IFERROR(RANK(Valor_normalizado!H72,Valor_normalizado!H$66:H$97,0),"NA")) -> 23 | I72: =IF(Valor_normalizado!I72=0,32,IFERROR(RANK(Valor_normalizado!I72,Valor_normalizado!I$66:I$97,0),"NA")) -> 16 | J72: =IF(Valor_normalizado!J72=0,32,IFERROR(RANK(Valor_normalizado!J72,Valor_normalizado!J$66:J$97,0),"NA")) -> 16 | ... Y72: =IF(Valor_normalizado!Y72=0,32,IFERROR(RANK(Valor_normalizado!Y72,Valor_normalizado!Y$66:Y$97,0),"NA")) -> 12
A73: Cúcuta AM | B73: 2021 | C73: =IF(Valor_normalizado!C73=0,32,IFERROR(RANK(Valor_normalizado!C73,Valor_normalizado!C$66:C$97,0),"NA")) -> 19 | D73: =IF(Valor_normalizado!D73=0,32,IFERROR(RANK(Valor_normalizado!D73,Valor_normalizado!D$66:D$97,0),"NA")) -> 9 | E73: =IF(Valor_normalizado!E73=0,32,IFERROR(RANK(Valor_normalizado!E73,Valor_normalizado!E$66:E$97,0),"NA")) -> 16 | F73: =IF(Valor_normalizado!F73=0,32,IFERROR(RANK(Valor_normalizado!F73,Valor_normalizado!F$66:F$97,0),"NA")) -> 15 | G73: =IF(Valor_normalizado!G73=0,32,IFERROR(RANK(Valor_normalizado!G73,Valor_normalizado!G$66:G$97,0),"NA")) -> 16 | H73: =IF(Valor_normalizado!H73=0,32,IFERROR(RANK(Valor_normalizado!H73,Valor_normalizado!H$66:H$97,0),"NA")) -> 19 | I73: =IF(Valor_normalizado!I73=0,32,IFERROR(RANK(Valor_normalizado!I73,Valor_normalizado!I$66:I$97,0),"NA")) -> 18 | J73: =IF(Valor_normalizado!J73=0,32,IFERROR(RANK(Valor_normalizado!J73,Valor_normalizado!J$66:J$97,0),"NA")) -> 20 | ... Y73: =IF(Valor_normalizado!Y73=0,32,IFERROR(RANK(Valor_normalizado!Y73,Valor_normalizado!Y$66:Y$97,0),"NA")) -> 17
A74: Florencia | B74: 2021 | C74: =IF(Valor_normalizado!C74=0,32,IFERROR(RANK(Valor_normalizado!C74,Valor_normalizado!C$66:C$97,0),"NA")) -> 21 | D74: =IF(Valor_normalizado!D74=0,32,IFERROR(RANK(Valor_normalizado!D74,Valor_normalizado!D$66:D$97,0),"NA")) -> 23 | E74: =IF(Valor_normalizado!E74=0,32,IFERROR(RANK(Valor_normalizado!E74,Valor_normalizado!E$66:E$97,0),"NA")) -> 19 | F74: =IF(Valor_normalizado!F74=0,32,IFERROR(RANK(Valor_normalizado!F74,Valor_normalizado!F$66:F$97,0),"NA")) -> 21 | G74: =IF(Valor_normalizado!G74=0,32,IFERROR(RANK(Valor_normalizado!G74,Valor_normalizado!G$66:G$97,0),"NA")) -> 20 | H74: =IF(Valor_normalizado!H74=0,32,IFERROR(RANK(Valor_normalizado!H74,Valor_normalizado!H$66:H$97,0),"NA")) -> 21 | I74: =IF(Valor_normalizado!I74=0,32,IFERROR(RANK(Valor_normalizado!I74,Valor_normalizado!I$66:I$97,0),"NA")) -> 25 | J74: =IF(Valor_normalizado!J74=0,32,IFERROR(RANK(Valor_normalizado!J74,Valor_normalizado!J$66:J$97,0),"NA")) -> 6 | ... Y74: =IF(Valor_normalizado!Y74=0,32,IFERROR(RANK(Valor_normalizado!Y74,Valor_normalizado!Y$66:Y$97,0),"NA")) -> 19
A75: Ibagué | B75: 2021 | C75: =IF(Valor_normalizado!C75=0,32,IFERROR(RANK(Valor_normalizado!C75,Valor_normalizado!C$66:C$97,0),"NA")) -> 9 | D75: =IF(Valor_normalizado!D75=0,32,IFERROR(RANK(Valor_normalizado!D75,Valor_normalizado!D$66:D$97,0),"NA")) -> 8 | E75: =IF(Valor_normalizado!E75=0,32,IFERROR(RANK(Valor_normalizado!E75,Valor_normalizado!E$66:E$97,0),"NA")) -> 10 | F75: =IF(Valor_normalizado!F75=0,32,IFERROR(RANK(Valor_normalizado!F75,Valor_normalizado!F$66:F$97,0),"NA")) -> 6 | G75: =IF(Valor_normalizado!G75=0,32,IFERROR(RANK(Valor_normalizado!G75,Valor_normalizado!G$66:G$97,0),"NA")) -> 9 | H75: =IF(Valor_normalizado!H75=0,32,IFERROR(RANK(Valor_normalizado!H75,Valor_normalizado!H$66:H$97,0),"NA")) -> 5 | I75: =IF(Valor_normalizado!I75=0,32,IFERROR(RANK(Valor_normalizado!I75,Valor_normalizado!I$66:I$97,0),"NA")) -> 5 | J75: =IF(Valor_normalizado!J75=0,32,IFERROR(RANK(Valor_normalizado!J75,Valor_normalizado!J$66:J$97,0),"NA")) -> 11 | ... Y75: =IF(Valor_normalizado!Y75=0,32,IFERROR(RANK(Valor_normalizado!Y75,Valor_normalizado!Y$66:Y$97,0),"NA")) -> 10
A76: Inírida | B76: 2021 | C76: =IF(Valor_normalizado!C76=0,32,IFERROR(RANK(Valor_normalizado!C76,Valor_normalizado!C$66:C$97,0),"NA")) -> 29 | D76: =IF(Valor_normalizado!D76=0,32,IFERROR(RANK(Valor_normalizado!D76,Valor_normalizado!D$66:D$97,0),"NA")) -> 31 | E76: =IF(Valor_normalizado!E76=0,32,IFERROR(RANK(Valor_normalizado!E76,Valor_normalizado!E$66:E$97,0),"NA")) -> 29 | F76: =IF(Valor_normalizado!F76=0,32,IFERROR(RANK(Valor_normalizado!F76,Valor_normalizado!F$66:F$97,0),"NA")) -> 30 | G76: =IF(Valor_normalizado!G76=0,32,IFERROR(RANK(Valor_normalizado!G76,Valor_normalizado!G$66:G$97,0),"NA")) -> 30 | H76: =IF(Valor_normalizado!H76=0,32,IFERROR(RANK(Valor_normalizado!H76,Valor_normalizado!H$66:H$97,0),"NA")) -> 24 | I76: =IF(Valor_normalizado!I76=0,32,IFERROR(RANK(Valor_normalizado!I76,Valor_normalizado!I$66:I$97,0),"NA")) -> 27 | J76: =IF(Valor_normalizado!J76=0,32,IFERROR(RANK(Valor_normalizado!J76,Valor_normalizado!J$66:J$97,0),"NA")) -> 6 | ... Y76: =IF(Valor_normalizado!Y76=0,32,IFERROR(RANK(Valor_normalizado!Y76,Valor_normalizado!Y$66:Y$97,0),"NA")) -> 31
A77: Leticia | B77: 2021 | C77: =IF(Valor_normalizado!C77=0,32,IFERROR(RANK(Valor_normalizado!C77,Valor_normalizado!C$66:C$97,0),"NA")) -> 31 | D77: =IF(Valor_normalizado!D77=0,32,IFERROR(RANK(Valor_normalizado!D77,Valor_normalizado!D$66:D$97,0),"NA")) -> 29 | E77: =IF(Valor_normalizado!E77=0,32,IFERROR(RANK(Valor_normalizado!E77,Valor_normalizado!E$66:E$97,0),"NA")) -> 32 | F77: =IF(Valor_normalizado!F77=0,32,IFERROR(RANK(Valor_normalizado!F77,Valor_normalizado!F$66:F$97,0),"NA")) -> 31 | G77: =IF(Valor_normalizado!G77=0,32,IFERROR(RANK(Valor_normalizado!G77,Valor_normalizado!G$66:G$97,0),"NA")) -> 32 | H77: =IF(Valor_normalizado!H77=0,32,IFERROR(RANK(Valor_normalizado!H77,Valor_normalizado!H$66:H$97,0),"NA")) -> 29 | I77: =IF(Valor_normalizado!I77=0,32,IFERROR(RANK(Valor_normalizado!I77,Valor_normalizado!I$66:I$97,0),"NA")) -> 30 | J77: =IF(Valor_normalizado!J77=0,32,IFERROR(RANK(Valor_normalizado!J77,Valor_normalizado!J$66:J$97,0),"NA")) -> 28 | ... Y77: =IF(Valor_normalizado!Y77=0,32,IFERROR(RANK(Valor_normalizado!Y77,Valor_normalizado!Y$66:Y$97,0),"NA")) -> 29
... A97: Yopal | B97: 2021 | C97: =IF(Valor_normalizado!C97=0,32,IFERROR(RANK(Valor_normalizado!C97,Valor_normalizado!C$66:C$97,0),"NA")) -> 12 | D97: =IF(Valor_normalizado!D97=0,32,IFERROR(RANK(Valor_normalizado!D97,Valor_normalizado!D$66:D$97,0),"NA")) -> 21 | E97: =IF(Valor_normalizado!E97=0,32,IFERROR(RANK(Valor_normalizado!E97,Valor_normalizado!E$66:E$97,0),"NA")) -> 11 | F97: =IF(Valor_normalizado!F97=0,32,IFERROR(RANK(Valor_normalizado!F97,Valor_normalizado!F$66:F$97,0),"NA")) -> 12 | G97: =IF(Valor_normalizado!G97=0,32,IFERROR(RANK(Valor_normalizado!G97,Valor_normalizado!G$66:G$97,0),"NA")) -> 13 | H97: =IF(Valor_normalizado!H97=0,32,IFERROR(RANK(Valor_normalizado!H97,Valor_normalizado!H$66:H$97,0),"NA")) -> 18 | I97: =IF(Valor_normalizado!I97=0,32,IFERROR(RANK(Valor_normalizado!I97,Valor_normalizado!I$66:I$97,0),"NA")) -> 20 | J97: =IF(Valor_normalizado!J97=0,32,IFERROR(RANK(Valor_normalizado!J97,Valor_normalizado!J$66:J$97,0),"NA")) -> 25 | ... Y97: =IF(Valor_normalizado!Y97=0,32,IFERROR(RANK(Valor_normalizado!Y97,Valor_normalizado!Y$66:Y$97,0),"NA")) -> 22
...

Sheet Pivot Table 1

Sheet RESULTADOS INN
A1: CODIGO_MUN | B1: CATEGORIA_NUM | C1: CATEGORIA_POBLACION | D1: Ciudad o AM | E1: 2019 | F1: 2020 | G1: 2021 | H1: 2022
A2: 1 | B2: 0 | C2: Superior o igual a 500,001 | D2: Bogotá D.C. | E2: 5.7505142 | F2: 5.9627539 | G2: 5.661942 | H2: 5.7957711
A3: 2 | B3: 0 | C3: Superior o igual a 500,001 | D3: Medellín AM | E3: 5.0481983 | F3: 5.6021917 | G3: 5.3879465 | H3: 5.2502314
A4: 5 | B4: 0 | C4: Superior o igual a 500,001 | D4: Cali AM | E4: 3.5121944 | F4: 3.8157236 | G4: 3.6605373 | H4: 3.5978347 | K4: Metodología: Muestra aleatoria simple
A5: 6 | B5: 0 | C5: Superior o igual a 500,001 | D5: Bucaramanga AM | E5: 3.1460224 | F5: 3.5144939 | G5: 3.8438224 | H5: 4.605215 | K5: Alcance: acciones específicas que definen su resultado
A6: 9 | B6: 0 | C6: Superior o igual a 500,001 | D6: Barranquilla AM | E6: 2.7576208 | F6: 3.4042264 | G6: 3.2774324 | H6: 3.5672449 | K6: acciones puntuales:
A7: 18 | B7: 0 | C7: Superior o igual a 500,001 | D7: Cartagena | E7: 1.472329 | F7: 1.5274334 | G7: 1.7550461 | H7: 2.0203776 | K7: 1. Construcción de base de datos de sub-pilares
